Workbook

Sheet Original Clinical
A1: Record ID | B1: Procedure(s) - notes | C1: Primary pre-operative diagnosis - checkboxes (choice=Coronary artery disease) | D1: Primary pre-operative diagnosis - checkboxes (choice=Valve disease) | E1: Primary pre-operative diagnosis - checkboxes (choice=Endocarditis) | F1: Primary pre-operative diagnosis - checkboxes (choice=Heart failure) | G1: Sex assigned at birth | H1: Age at enrollment | I1: Ethnicity | J1: Race | K1: BMI | L1: Smoking | M1: Current smoker | N1: Diabetes | O1: History of cancer | P1: Cancer type, years since treatment, other | Q1: Hypertension | R1: Peripheral vascular disease | S1: Hyperlipidemia | T1: Stroke | U1: Hypothyroidism | V1: Autoimmune disease | W1: History of thrombosis/pulmonary embolism
A2: 1001 | B2: Repair Mitral Valve | C2: Unchecked | D2: Checked | E2: Unchecked | F2: Unchecked | G2: Female | H2: 34 | I2: Not Hispanic or Latino | J2: White | K2: 23.9 | L2: No | N2: No | O2: No | Q2: No | R2: No | S2: No | T2: No | U2: No | V2: No | W2: No
A3: 1003 | B3: REPLACE SYSTEMIC TRICUSPID VALVE IN CCTGA CLOSURE PATENT FORAMEN OVALE PLACEMENT VENTRICUALR EPICARDIAL LEADS | C3: Unchecked | D3: Checked | E3: Unchecked | F3: Unchecked | G3: Female | H3: 35 | I3: Not Hispanic or Latino | J3: White | K3: 26.5 | L3: No | N3: No | O3: No | Q3: No | R3: No | S3: No | T3: No | U3: No | V3: No | W3: No
A4: 1004 | B4: REPLACEMENT AORTIC VALVE REPLACEMENT HEMI ARCH ASCENDING AORTIC ANEURYSM MAZE PROCEDURE AMPUTATION LEFT ATRIAL APPENDAGE | C4: Unchecked | D4: Checked | E4: Unchecked | F4: Unchecked | G4: Male | H4: 68 | I4: Not Hispanic or Latino | J4: White | K4: 27.1 | L4: No | N4: No | O4: No | Q4: No | R4: No | S4: No | T4: No | U4: No | V4: No | W4: No
A5: 1008 | B5: EXPLORATION AORTIC VALVE REPLACEMENT MITRAL VALVE AMPUTATION LEFT ATRIAL APPENDAGE ISOLATION PULMONARY VEIN | C5: Unchecked | D5: Checked | E5: Unchecked | F5: Unchecked | G5: Male | H5: 71 | I5: Not Hispanic or Latino | J5: White | K5: 19.3 | L5: Yes | M5: No | N5: No | O5: No | Q5: No | R5: No | S5: No | T5: No | U5: No | V5: No | W5: No
A6: 1010 | B6: CORONARY ARTERY BYPASS GRAFT x3, USING LIMA AND LEFT SAPHENOUS VEIN GRAFT (EVH) | C6: Checked | D6: Unchecked | E6: Unchecked | F6: Unchecked | G6: Female | H6: 70 | I6: Not Hispanic or Latino | J6: White | K6: 21.6 | L6: No | N6: Yes | O6: No | Q6: Yes | R6: No | S6: Yes | T6: No | U6: No | V6: No | W6: No
A7: 1012 | B7: Reconstruction or replacement valve sparing aortic root | C7: Unchecked | D7: Unchecked | E7: Unchecked | F7: Unchecked | G7: Female | H7: 31 | I7: Unavailable | J7: Unavailable | K7: 18.3 | L7: No | N7: No | O7: No | Q7: No | R7: No | S7: No | T7: No | U7: No | V7: No | W7: No
A8: 1013 | B8: Coronary Artery Bypass Isolation pulmonary vein | C8: Checked | D8: Unchecked | E8: Unchecked | F8: Unchecked | G8: Male | H8: 65 | I8: Not Hispanic or Latino | J8: White | K8: 32.6 | L8: No | N8: No | O8: Yes | P8: Prostate cancer 2019 no surgery, currently on Lupron Q 3 months and daily Zytiga and Prednisone | Q8: Yes | R8: No | S8: Yes | T8: No | U8: No | V8: No | W8: No
A9: 1014 | B9: CORONARY ARTERY BYPASS GRAFT x 3 with SVG and LIMA, ENDOSCOPIC SAPHENOUS VEIN HARVEST LEFT LEG | C9: Checked | D9: Unchecked | E9: Unchecked | F9: Unchecked | G9: Male | H9: 75 | I9: Not Hispanic or Latino | J9: White | K9: 22.3 | L9: Yes | M9: No | N9: No | O9: No | Q9: No | R9: No | S9: Yes | T9: No | U9: Yes | V9: No | W9: No
A10: 1015 | B10: THROMBOENDARTERECTOMY PULMONARY ARTERY WITH CARDIAC ARREST REPAIR TRICUSPID VALVE | C10: Unchecked | D10: Checked | E10: Unchecked | F10: Unchecked | G10: Female | H10: 34 | I10: Not Hispanic or Latino | J10: White | K10: 41.9 | L10: Yes | M10: No | N10: No | O10: No | Q10: No | R10: No | S10: No | T10: No | U10: No | V10: No | W10: Yes
A11: 1016 | B11: CORONARY ARTERY BYPASS GRAFT X2 W/ LIMA AND LEFT LEG ENDOSCOPIC SAPHENOUS VEIN HARVEST | C11: Checked | D11: Unchecked | E11: Unchecked | F11: Checked | G11: Male | H11: 78 | I11: Not Hispanic or Latino | J11: White | K11: 24.6 | L11: Yes | M11: No | N11: No | O11: No | Q11: Yes | R11: Yes | S11: Yes | T11: No | U11: No | V11: No | W11: No
A12: 1020 | B12: Replacement Aortic Valve | C12: Unchecked | D12: Checked | E12: Unchecked | F12: Unchecked | G12: Female | H12: 66 | I12: Not Hispanic or Latino | J12: White | K12: 24.2 | L12: Yes | M12: No | N12: No | O12: No | Q12: Yes | R12: No | S12: Yes | T12: No | U12: No | V12: No | W12: No
A13: 1021 | B13: CORONARY ARTERY BYPASS GRAFT OFF PUMP X 2 | C13: Checked | D13: Unchecked | E13: Unchecked | F13: Unchecked | G13: Female | H13: 71 | I13: Not Hispanic or Latino | J13: White | K13: 34.6 | L13: Yes | M13: No | N13: No | O13: Yes | P13: right lung cancer s/p resection of RUL in 2010 and radiation and 2010 and 2017 with mets to left adrenal gland s/p L adrenalectomy | Q13: Yes | R13: No | S13: Yes | T13: No | U13: No | V13: No | W13: No
A14: 1022 | B14: REPLACEMENT MITRAL VALVE RESECTION MASS AORTIC VALVE REPAIR TRICUSPID VALVE MAZE PROCEDURE, LEFT ATRIAL APPENDAGE AMPUTATION, RIGHT ATRIAL REDUCTION | C14: Checked | D14: Checked | E14: Unchecked | F14: Checked | G14: Female | H14: 79 | I14: Not Hispanic or Latino | J14: White | K14: 22.1 | L14: No | N14: No | O14: No | Q14: Yes | R14: No | S14: Yes | T14: Yes | U14: No | V14: No | W14: No
A15: 1023 | B15: CORONARY ARTERY BYPASS GRAFT x 3 with LIMA and SVG, ENDOSCOPIC SAPHENOUS VEIN HARVEST LEFT LEG | C15: Checked | D15: Unchecked | E15: Unchecked | F15: Unchecked | G15: Male | H15: 47 | I15: Not Hispanic or Latino | J15: White | K15: 27 | L15: Yes | M15: No | N15: No | O15: No | Q15: Yes | R15: No | S15: Yes | T15: Yes | U15: No | V15: No | W15: No
A16: 1026 | B16: CORONARY ARTERY BYPASS GRAFT x1, LEFT SAPHENOUS EVH | C16: Checked | D16: Unchecked | E16: Unchecked | F16: Unchecked | G16: Female | H16: 58 | I16: Hispanic or Latino | J16: Unavailable | K16: 30.7 | L16: No | N16: No | O16: No | Q16: Yes | R16: No | S16: Yes | T16: No | U16: No | V16: No | W16: No
A17: 1031 | B17: CORONARY ARTERY BYPASS GRAFT X5, LIMA, LEFT AND RIGHT LEG SAPHENOUS EVH | C17: Checked | D17: Unchecked | E17: Unchecked | F17: Unchecked | G17: Male | H17: 63 | I17: Not Hispanic or Latino | J17: White | K17: 34.1 | L17: Yes | M17: Yes | N17: Yes | O17: No | Q17: Yes | R17: No | S17: Yes | T17: No | U17: No | V17: No | W17: No
A18: 1033 | B18: REPLACEMENT AORTIC VALVE CORONARY ARTERY BYPASS GRAFT x3, LEFT LEG ENDOSCOPIC SAPHENOUS VEIN HARVEST | C18: Checked | D18: Checked | E18: Unchecked | F18: Unchecked | G18: Male | H18: 79 | I18: Not Hispanic or Latino | J18: White | K18: 21.8 | L18: Yes | M18: No | N18: No | O18: Yes | P18: Adenocarcinoma of left lung 2021 | Q18: Yes | R18: Yes | S18: No | T18: No | U18: Yes | V18: No | W18: No
A19: 1039 | B19: REPLACEMENT AORTIC VALVE (BIO), AORTIC ROOT ENLARGEMENT | C19: Unchecked | D19: Checked | E19: Unchecked | F19: Unchecked | G19: Female | H19: 56 | I19: Not Hispanic or Latino | J19: White | K19: 41.6 | L19: No | N19: Yes | O19: No | Q19: Yes | R19: No | S19: Yes | T19: No | U19: Yes | V19: No | W19: No
A20: 1040 | B20: CORONARY ARTERY BYPASS GRAFT x1, LIMA, LEFT SAPHENOUS VEIN HARVEST (EVH) REPLACEMENT AORTIC VALVE | C20: Checked | D20: Checked | E20: Unchecked | F20: Unchecked | G20: Female | H20: 80 | I20: Not Hispanic or Latino | J20: White | K20: 41.9 | L20: Yes | M20: No | N20: No | O20: Yes | P20: Skin Cancer | Q20: Yes | R20: No | S20: Yes | T20: No | U20: No | V20: Yes | W20: No
A21: 1046 | B21: REPLACEMENT AORTIC VALVE CABG X 1, LEFT SV ENDOHARVEST | C21: Checked | D21: Checked | E21: Unchecked | F21: Unchecked | G21: Male | H21: 58 | I21: Not Hispanic or Latino | J21: White | K21: 32.8 | L21: Yes | M21: Yes | N21: Yes | O21: No | Q21: Yes | R21: No | S21: Yes | T21: No | U21: No | V21: No | W21: No
A22: 1047 | B22: COMPOSITE AORTIC ROOT, RECONSTRUCTION HEMIARCH REPLACEMENT VALVE SPARING AORTIC ROOT MAZE PROCEDURE/ Left atrial appendage ligation | C22: Unchecked | D22: Checked | E22: Unchecked | F22: Unchecked | G22: Male | H22: 69 | I22: Not Hispanic or Latino | J22: White | K22: 23.5 | L22: No | N22: No | O22: No | Q22: Yes | R22: No | S22: Yes | T22: No | U22: No | V22: No | W22: No
A23: 1048 | B23: Removal of Right atrial foreing body, PARASTERNAL BLOCK REPAIR TRICUSPID VALVE | C23: Unchecked | D23: Checked | E23: Unchecked | F23: Unchecked | G23: Female | H23: 24 | I23: Not Hispanic or Latino | J23: White | K23: 25.4 | L23: No | N23: No | O23: No | Q23: No | R23: Yes | S23: No | T23: No | U23: No | V23: No | W23: No
A24: 1050 | B24: CORONARY ARTERY BYPASS GRAFT X 4, LEFT SV HARVEST, LIMA | C24: Checked | D24: Unchecked | E24: Unchecked | F24: Unchecked | G24: Male | H24: 70 | I24: Not Hispanic or Latino | J24: White | K24: 34.6 | L24: Yes | M24: No | N24: Yes | O24: No | Q24: Yes | R24: No | S24: Yes | T24: No | U24: No | V24: No | W24: No
A25: 1059 | B25: REPLACEMENT AORTIC VALVE MAZE PROCEDURE/ left atrial appendage resection AORTIC ROOT enlargement | C25: Unchecked | D25: Checked | E25: Unchecked | F25: Unchecked | G25: Female | H25: 60 | I25: Not Hispanic or Latino | J25: White | K25: 38.4 | L25: Yes | M25: No | N25: No | O25: No | Q25: Yes | R25: No | S25: No | T25: No | U25: No | V25: No | W25: No
A26: 1061 | B26: REVISION AORTIC VALVE REPLACEMENT, AORTOPLASTY AORTIC ROOT ENLARGEMENT | C26: Unchecked | D26: Unchecked | E26: Unchecked | F26: Unchecked | G26: Female | H26: 49 | I26: Not Hispanic or Latino | J26: White | K26: 27.8 | L26: Yes | M26: No | N26: No | O26: No | Q26: No | R26: No | S26: Yes | T26: No | U26: No | V26: Yes | W26: No
A27: 1066 | B27: CORONARY ARTERY BYPASS GRAFT x 6 with BIMA and SVG, ENDOSCOPIC SAPHENOUS VEIN HARVEST BILATERAL LEGS | C27: Checked | D27: Unchecked | E27: Unchecked | F27: Unchecked | G27: Male | H27: 55 | I27: Not Hispanic or Latino | J27: White | K27: 31.1 | L27: No | N27: No | O27: No | Q27: No | R27: No | S27: Yes | T27: No | U27: No | V27: No | W27: No
A28: 1069 | B28: CORONARY ARTERY BYPASS GRAFT x2, LEFT SVG | C28: Checked | D28: Unchecked | E28: Unchecked | F28: Unchecked | G28: Female | H28: 62 | I28: Unavailable | J28: Unavailable | K28: 31.6 | L28: No | N28: No | O28: No | Q28: No | R28: No | S28: Yes | T28: No | U28: No | V28: No | W28: No
A29: 1073 | B29: Ascending aortic replacement (22 mm Gelweave tube graft/28 mm Gelweave tube graft). | C29: Unchecked | D29: Unchecked | E29: Unchecked | F29: Unchecked | G29: Female | H29: 78 | I29: Not Hispanic or Latino | J29: White | K29: 33.7 | L29: Yes | M29: No | N29: No | O29: No | Q29: Yes | R29: No | S29: No | T29: No | U29: Yes | V29: No | W29: No
A30: 1086 | B30: REPLACEMENT AORTIC VALVE REPAIR ANEURYSM HEMI ARCH ASCENDING AORTA, ERAS | C30: Unchecked | D30: Checked | E30: Unchecked | F30: Unchecked | G30: Male | H30: 65 | I30: Not Hispanic or Latino | J30: White | K30: 42.6 | L30: No | N30: No | O30: No | Q30: No | R30: No | S30: Yes | T30: No | U30: No | V30: No | W30: No
A31: 1090 | B31: MYECTOMY SEPTAL, ERAS | C31: Unchecked | D31: Unchecked | E31: Unchecked | F31: Unchecked | G31: Male | H31: 29 | I31: Not Hispanic or Latino | J31: White | K31: 26.2 | L31: No | N31: No | O31: No | Q31: No | R31: No | S31: No | T31: No | U31: No | V31: No | W31: No
A32: 1091 | B32: BENTALL WITH ASCENDING HEMIARCH, LEFT LEG ENDOSCOPIC SAPHENOUS VEIN HARVEST | C32: Unchecked | D32: Checked | E32: Unchecked | F32: Checked | G32: Female | H32: 61 | I32: Not Hispanic or Latino | J32: White | K32: 33.8 | L32: No | N32: No | O32: No | Q32: Yes | R32: No | S32: Yes | T32: No | U32: No | V32: No | W32: No
A33: 1096 | B33: CORONARY ARTERY BYPASS GRAFT x4, LEFT LEG ENDOSCOPIC SAPHENOUS VEIN HARVEST | C33: Checked | D33: Unchecked | E33: Unchecked | F33: Unchecked | G33: Male | H33: 66 | I33: Not Hispanic or Latino | J33: More than One Race | K33: 34.1 | L33: Yes | M33: No | N33: No | O33: No | Q33: Yes | R33: No | S33: Yes | T33: No | U33: No | V33: No | W33: No
A34: 1097 | B34: MYECTOMY SEPTAL(ERAS) | C34: Unchecked | D34: Checked | E34: Unchecked | F34: Unchecked | G34: Male | H34: 68 | I34: Not Hispanic or Latino | J34: White | K34: 37.4 | L34: No | N34: No | O34: No | Q34: No | R34: No | S34: Yes | T34: No | U34: No | V34: No | W34: Yes
A35: 1102 | B35: REPLACEMENT AORTIC VALVE(ERAS) REPAIR OR REPLACEMENT HEMI ARCH ASCENDING AORTA | C35: Unchecked | D35: Checked | E35: Unchecked | F35: Unchecked | G35: Female | H35: 57 | I35: Not Hispanic or Latino | J35: White | K35: 34.2 | L35: No | N35: Yes | O35: No | Q35: Yes | R35: No | S35: No | T35: No | U35: No | V35: No | W35: No
A36: 1103 | B36: REPLACEMENT AORTIC VALVE REPLACEMENT HEMI ARCH ASCENDING AORTA CORONARY ARTERY BYPASS GRAFT x2 WITH LEFT LEG ENDOSCOPIC SAPHENOUS VEIN HARVEST | C36: Checked | D36: Checked | E36: Unchecked | F36: Unchecked | G36: Male | H36: 67 | I36: Not Hispanic or Latino | J36: White | K36: 24.7 | L36: No | N36: Yes | O36: No | Q36: Yes | R36: No | S36: Yes | T36: No | U36: No | V36: No | W36: No
A37: 1107 | B37: REVISION CORONARY ARTERY BYPASS GRAFT WITH ALLOGRAFT SAPHENOUS VEIN x3, SAPHENOUS TO LIMA COMPOSITE GRAFT. ATTEMPTED ENDOSCOPIC HARVESTING VEIN RIGHT INTERNAL MAMMARY ARTERY TAKEDOWN | C37: Checked | D37: Unchecked | E37: Unchecked | F37: Unchecked | G37: Male | H37: 60 | I37: Not Hispanic or Latino | J37: White | K37: 30.3 | L37: Yes | M37: Yes | N37: Yes | O37: No | Q37: Yes | R37: No | S37: No | T37: No | U37: No | V37: No | W37: No
A38: 1118 | B38: OFF PUMP CABG x 1, LIMA-LAD | C38: Checked | D38: Unchecked | E38: Unchecked | F38: Unchecked | G38: Male | H38: 41 | I38: Not Hispanic or Latino | J38: White | K38: 50.9 | L38: Yes | M38: No | N38: No | O38: No | Q38: Yes | R38: No | S38: Yes | T38: No | U38: No | V38: No | W38: No
A39: 1121 | B39: CORONARY ARTERY BYPASS GRAFT X 3 with LIMA and SVG , ENDARTERECTOMY, ENDOSCOPIC SAPHENOUS VEIN HARVEST LEFT LEG , ERAS INSERTION OF CENTRIMAG RIGHT VENTRICULAR ASSIST DEVICE | C39: Checked | D39: Unchecked | E39: Unchecked | F39: Unchecked | G39: Male | H39: 69 | I39: Not Hispanic or Latino | J39: Asian | K39: 22 | L39: No | N39: Yes | O39: No | Q39: Yes | R39: No | S39: Yes | T39: No | U39: No | V39: No | W39: No
A40: 1145 | B40: Replacement Aortic Valve, ERAS Coronary Artery Bypass Graft | C40: Checked | D40: Checked | E40: Unchecked | F40: Unchecked | G40: Male | H40: 73 | I40: Not Hispanic or Latino | J40: White | K40: 31.3 | L40: No | N40: No | O40: Yes | P40: Prostate cancer, s/p radiation, s/p XRT . Followed DFCI SSH , 2019 | Q40: Yes | R40: No | S40: Yes | T40: No | U40: No | V40: No | W40: No
...

Sheet Original Count data
A1: file | B1: FlowCut-passed/Cells|count | C1: FlowCut-passed/Cells/Single Cells|count | D1: FlowCut-passed/Cells/Single Cells/Live Cells|count | E1: FlowCut-passed/Cells/Single Cells/Live Cells/CD45+|count | F1: FlowCut-passed/Cells/Single Cells/Live Cells/CD45+/CD3-/CD34+|count | G1: FlowCut-passed/Cells/Single Cells/Live Cells/CD45+/CD3-/CD34+/CD4-CD56-|count | H1: FlowCut-passed/Cells/Single Cells/Live Cells/CD45+/CD3-/CD34+/CD4-CD56-/CD20-CD123-|count | I1: FlowCut-passed/Cells/Single Cells/Live Cells/CD45+/CD3-/CD34+/CD4-CD56-/CD20-CD123-/CD14-CD16-|count | J1: FlowCut-passed/Cells/Single Cells/Live Cells/CD45+/CD3-/CD34+/CD4-CD56-/CD20-CD123-/CD14-CD16-/CD11b-CD11c-|count | K1: FlowCut-passed/Cells/Single Cells/Live Cells/CD45+/CD3-/CD34+/CD4-CD56-/CD20-CD123-/CD14-CD16-/CD11b-CD11c-/CD34+CD38-|count | L1: FlowCut-passed/Cells/Single Cells/Live Cells/CD45+/CD3-/CD34+/CD4-CD56-/CD20-CD123-/CD14-CD16-/CD11b-CD11c-/CD34+CD38+|count | M1: FlowCut-passed/Cells/Single Cells/Live Cells/CD45+/CD3-/CD34+/CD4-CD56-/CD20-CD123-/CD14-CD16-/CD11b-CD11c-/CD34+CD38+/Pro-B|count | N1: FlowCut-passed/Cells/Single Cells/Live Cells/CD45+/CD3-/CD34+/CD4-CD56-/CD20-CD123-/CD14-CD16-/CD11b-CD11c-/CD34+CD38+/Pre-pro-B|count | O1: FlowCut-passed/Cells/Single Cells/Live Cells/CD45+/CD3-/CD34-|count | P1: FlowCut-passed/Cells/Single Cells/Live Cells/CD45+/CD3-/CD34-/B Cells|count | Q1: FlowCut-passed/Cells/Single Cells/Live Cells/CD45+/CD3-/CD34-/CD19-/CD20-|count | R1: FlowCut-passed/Cells/Single Cells/Live Cells/CD45+/CD3-/CD34-/CD19-/CD20-/Early NK|count | S1: FlowCut-passed/Cells/Single Cells/Live Cells/CD45+/CD3-/CD34-/CD19-/CD20-/Mature NK|count | T1: FlowCut-passed/Cells/Single Cells/Live Cells/CD45+/CD3-/CD34-/CD19-/CD20-/Non-Classical Monocyte|count | U1: FlowCut-passed/Cells/Single Cells/Live Cells/CD45+/CD3-/CD34-/CD19-/CD20-/Classical Monocyte|count | V1: FlowCut-passed/Cells/Single Cells/Live Cells/CD45+/CD3-/CD34-/CD19-/CD20-/CD14+/HLA-DR-|count | W1: FlowCut-passed/Cells/Single Cells/Live Cells/CD45+/CD3-/CD34-/CD19-/CD20-/CD14+/HLA-DR-/MDSC-like|count | X1: FlowCut-passed/Cells/Single Cells/Live Cells/CD45+/CD3-/CD34-/CD19-/CD20-/Dendritic Cells|count | Y1: FlowCut-passed/Cells/Single Cells/Live Cells/CD45+/CD3-/CD34-/CD19-/CD20-/Dendritic Cells/pDC|count | Z1: FlowCut-passed/Cells/Single Cells/Live Cells/CD45+/CD3-/CD34-/CD19-/CD20-/Dendritic Cells/cDC|count | AA1: FlowCut-passed/Cells/Single Cells/Live Cells/CD45+/CD3-/CD34-/CD19-/CD20-/Dendritic Cells/cDC/CD16+ cDC|count | AB1: FlowCut-passed/Cells/Single Cells/Live Cells/CD45+/CD3-/CD34-/CD19-/CD20-/Dendritic Cells/cDC/CD16- cDC|count | AC1: FlowCut-passed/Cells/Single Cells/Live Cells/CD45+/CD3-/CD34-/CD19-/CD20-/CD14-/HLA-DR-|count | AD1: FlowCut-passed/Cells/Single Cells/Live Cells/CD45+/CD3-/CD34-/CD19-/CD20-/CD14-/HLA-DR-/ILC|count | AE1: FlowCut-passed/Cells/Single Cells/Live Cells/CD45+/CD3+/CD34-|count | AF1: FlowCut-passed/Cells/Single Cells/Live Cells/CD45+/CD3+/CD34-/TCRab+|count | AG1: FlowCut-passed/Cells/Single Cells/Live Cells/CD45+/CD3+/CD34-/TCRab+/NKT CD8-|count | AH1: FlowCut-passed/Cells/Single Cells/Live Cells/CD45+/CD3+/CD34-/TCRab+/NKT CD8+|count | AI1: FlowCut-passed/Cells/Single Cells/Live Cells/CD45+/CD3+/CD34-/TCRab+/T Cell|count | AJ1: FlowCut-passed/Cells/Single Cells/Live Cells/CD45+/CD3+/CD34-/TCRab+/T Cell/CD4+ T cell|count | AK1: FlowCut-passed/Cells/Single Cells/Live Cells/CD45+/CD3+/CD34-/TCRab+/T Cell/CD4+ T cell/Tregs|count | AL1: FlowCut-passed/Cells/Single Cells/Live Cells/CD45+/CD3+/CD34-/TCRab+/T Cell/CD4+ T cell/CD4+/CD197+|count | AM1: FlowCut-passed/Cells/Single Cells/Live Cells/CD45+/CD3+/CD34-/TCRab+/T Cell/CD4+ T cell/CD4+/CD197+/Naive CD4+ T Cell|count | AN1: FlowCut-passed/Cells/Single Cells/Live Cells/CD45+/CD3+/CD34-/TCRab+/T Cell/CD4+ T cell/CD4+/CD197+/Central Memory CD4+ T Cell|count | AO1: FlowCut-passed/Cells/Single Cells/Live Cells/CD45+/CD3+/CD34-/TCRab+/T Cell/CD4+ T cell/CD4+/CD197-|count | AP1: FlowCut-passed/Cells/Single Cells/Live Cells/CD45+/CD3+/CD34-/TCRab+/T Cell/CD4+ T cell/CD4+/CD197-/Effector CD4+ T Cell|count | AQ1: FlowCut-passed/Cells/Single Cells/Live Cells/CD45+/CD3+/CD34-/TCRab+/T Cell/CD4+ T cell/CD279+/CD4+ T Cell|count | AR1: FlowCut-passed/Cells/Single Cells/Live Cells/CD45+/CD3+/CD34-/TCRab+/T Cell/CD4+ T cell/CD279+/CD4+ T Cell/CD4+ TPex|count | AS1: FlowCut-passed/Cells/Single Cells/Live Cells/CD45+/CD3+/CD34-/TCRab+/T Cell/CD8+ T Cell|count | AT1: FlowCut-passed/Cells/Single Cells/Live Cells/CD45+/CD3+/CD34-/TCRab+/T Cell/CD8+ T Cell/CD279+/CD8+ T Cell|count | AU1: FlowCut-passed/Cells/Single Cells/Live Cells/CD45+/CD3+/CD34-/TCRab+/T Cell/CD8+ T Cell/CD279+/CD8+ T Cell/CD8+ TPex|count | AV1: FlowCut-passed/Cells/Single Cells/Live Cells/CD45+/CD3+/CD34-/TCRab+/T Cell/CD8+ T Cell/CD197+/CD8+ T Cell|count | AW1: FlowCut-passed/Cells/Single Cells/Live Cells/CD45+/CD3+/CD34-/TCRab+/T Cell/CD8+ T Cell/CD197+/CD8+ T Cell/Central Memory CD8+ T Cell|count | AX1: FlowCut-passed/Cells/Single Cells/Live Cells/CD45+/CD3+/CD34-/TCRab+/T Cell/CD8+ T Cell/CD197+/CD8+ T Cell/Naive CD8+ T Cell|count | AY1: FlowCut-passed/Cells/Single Cells/Live Cells/CD45+/CD3+/CD34-/TCRab+/T Cell/CD8+ T Cell/CD197-/CD8+ T Cell|count | AZ1: FlowCut-passed/Cells/Single Cells/Live Cells/CD45+/CD3+/CD34-/TCRab+/T Cell/CD8+ T Cell/CD197-/CD8+ T Cell/Effector CD8+ T Cell|count | BA1: FlowCut-passed/Cells/Single Cells/Live Cells/CD45+/CD3+/CD34-/gd T cell|count
A2: SBM1001.fcs | B2: 277764 | C2: 265500 | D2: 262632 | E2: 102216 | F2: 2698 | G2: 2649 | H2: 2482 | I2: 2472 | J2: 2463 | K2: 547 | L2: 1517 | M2: 53 | N2: 86 | O2: 38541 | P2: 7265 | Q2: 29957 | R2: 1300 | S2: 889 | T2: 1026 | U2: 13380 | V2: 5675 | W2: 5624 | X2: 8258 | Y2: 2276 | Z2: 5095 | AA2: 42 | AB2: 4884 | AC2: 5749 | AD2: 106 | AE2: 58069 | AF2: 55511 | AG2: 301 | AH2: 176 | AI2: 53861 | AJ2: 32786 | AK2: 130 | AL2: 19853 | AM2: 15656 | AN2: 3132 | AO2: 7645 | AP2: 6090 | AQ2: 1144 | AR2: 201 | AS2: 19694 | AT2: 1655 | AU2: 130 | AV2: 7234 | AW2: 298 | AX2: 6835 | AY2: 11340 | AZ2: 5716 | BA2: 154
A3: SBM1003.fcs | B3: 321845 | C3: 314310 | D3: 309191 | E3: 181785 | F3: 3329 | G3: 3197 | H3: 2976 | I3: 2935 | J3: 2904 | K3: 1162 | L3: 407 | M3: 9 | N3: 20 | O3: 90578 | P3: 35124 | Q3: 51872 | R3: 1659 | S3: 927 | T3: 2509 | U3: 21579 | V3: 11303 | W3: 10861 | X3: 13356 | Y3: 2863 | Z3: 8637 | AA3: 317 | AB3: 6310 | AC3: 9556 | AD3: 122 | AE3: 82123 | AF3: 75753 | AG3: 618 | AH3: 651 | AI3: 72429 | AJ3: 46060 | AK3: 125 | AL3: 38228 | AM3: 36081 | AN3: 1486 | AO3: 5701 | AP3: 2403 | AQ3: 5549 | AR3: 3054 | AS3: 24060 | AT3: 3824 | AU3: 736 | AV3: 8187 | AW3: 89 | AX3: 7976 | AY3: 15216 | AZ3: 788 | BA3: 165
A4: SBM1004.fcs | B4: 303378 | C4: 294206 | D4: 293104 | E4: 123429 | F4: 1998 | G4: 1955 | H4: 1890 | I4: 1861 | J4: 1855 | K4: 613 | L4: 927 | M4: 22 | N4: 32 | O4: 29560 | P4: 2362 | Q4: 26672 | R4: 1932 | S4: 3761 | T4: 4628 | U4: 9325 | V4: 247 | W4: 234 | X4: 3798 | Y4: 831 | Z4: 2116 | AA4: 104 | AB4: 1905 | AC4: 12819 | AD4: 385 | AE4: 89371 | AF4: 81626 | AG4: 368 | AH4: 1572 | AI4: 77563 | AJ4: 35933 | AK4: 693 | AL4: 11210 | AM4: 2531 | AN4: 7689 | AO4: 22284 | AP4: 22077 | AQ4: 1226 | AR4: 243 | AS4: 38816 | AT4: 5337 | AU4: 346 | AV4: 764 | AW4: 401 | AX4: 306 | AY4: 37407 | AZ4: 14084 | BA4: 126
A5: SBM1008.fcs | B5: 47011 | C5: 45318 | D5: 44254 | E5: 27384 | F5: 190 | G5: 182 | H5: 169 | I5: 165 | J5: 163 | K5: 44 | L5: 104 | M5: 0 | N5: 0 | O5: 13407 | P5: 3105 | Q5: 9778 | R5: 647 | S5: 266 | T5: 438 | U5: 4268 | V5: 564 | W5: 516 | X5: 2355 | Y5: 374 | Z5: 1642 | AA5: 13 | AB5: 1617 | AC5: 2487 | AD5: 61 | AE5: 13320 | AF5: 12779 | AG5: 221 | AH5: 168 | AI5: 11903 | AJ5: 9575 | AK5: 12 | AL5: 7111 | AM5: 2140 | AN5: 4244 | AO5: 1849 | AP5: 1802 | AQ5: 826 | AR5: 357 | AS5: 2032 | AT5: 325 | AU5: 91 | AV5: 1281 | AW5: 85 | AX5: 1159 | AY5: 679 | AZ5: 496 | BA5: 3
A6: SBM1010.fcs | B6: 284997 | C6: 278506 | D6: 276399 | E6: 216305 | F6: 548 | G6: 536 | H6: 501 | I6: 496 | J6: 491 | K6: 114 | L6: 272 | M6: 3 | N6: 0 | O6: 124747 | P6: 20381 | Q6: 102697 | R6: 3254 | S6: 8529 | T6: 16692 | U6: 57126 | V6: 23217 | W6: 23059 | X6: 10814 | Y6: 1135 | Z6: 8786 | AA6: 3198 | AB6: 4026 | AC6: 28333 | AD6: 165 | AE6: 88203 | AF6: 84921 | AG6: 1050 | AH6: 568 | AI6: 79921 | AJ6: 35897 | AK6: 330 | AL6: 18789 | AM6: 6577 | AN6: 10997 | AO6: 15251 | AP6: 14633 | AQ6: 5380 | AR6: 1510 | AS6: 40007 | AT6: 7521 | AU6: 1434 | AV6: 7200 | AW6: 1680 | AX6: 5258 | AY6: 31488 | AZ6: 14743 | BA6: 49
A7: SBM1012.fcs | B7: 270926 | C7: 265202 | D7: 261135 | E7: 167832 | F7: 1547 | G7: 1516 | H7: 1454 | I7: 1439 | J7: 1432 | K7: 639 | L7: 612 | M7: 16 | N7: 20 | O7: 100530 | P7: 24253 | Q7: 71034 | R7: 2153 | S7: 2647 | T7: 4370 | U7: 27309 | V7: 9535 | W7: 9282 | X7: 21634 | Y7: 4506 | Z7: 13647 | AA7: 155 | AB7: 12386 | AC7: 15506 | AD7: 214 | AE7: 63098 | AF7: 60720 | AG7: 522 | AH7: 519 | AI7: 57375 | AJ7: 25309 | AK7: 208 | AL7: 12451 | AM7: 7555 | AN7: 3972 | AO7: 10943 | AP7: 10584 | AQ7: 2019 | AR7: 434 | AS7: 29360 | AT7: 5302 | AU7: 760 | AV7: 12353 | AW7: 888 | AX7: 11077 | AY7: 15587 | AZ7: 10183 | BA7: 21
A8: SBM1013.fcs | B8: 36817 | C8: 34554 | D8: 33806 | E8: 10634 | F8: 215 | G8: 215 | H8: 203 | I8: 203 | J8: 203 | K8: 119 | L8: 60 | M8: 8 | N8: 4 | O8: 5790 | P8: 1094 | Q8: 4532 | R8: 435 | S8: 813 | T8: 923 | U8: 785 | V8: 219 | W8: 182 | X8: 892 | Y8: 130 | Z8: 596 | AA8: 59 | AB8: 458 | AC8: 2512 | AD8: 10 | AE8: 4397 | AF8: 4172 | AG8: 68 | AH8: 103 | AI8: 3741 | AJ8: 2651 | AK8: 12 | AL8: 1277 | AM8: 241 | AN8: 956 | AO8: 1103 | AP8: 1096 | AQ8: 206 | AR8: 74 | AS8: 939 | AT8: 227 | AU8: 66 | AV8: 190 | AW8: 75 | AX8: 105 | AY8: 693 | AZ8: 438 | BA8: 3
A9: SBM1014.fcs | B9: 112228 | C9: 110574 | D9: 108857 | E9: 49789 | F9: 975 | G9: 936 | H9: 914 | I9: 908 | J9: 907 | K9: 749 | L9: 26 | M9: 0 | N9: 0 | O9: 20845 | P9: 3782 | Q9: 16514 | R9: 2447 | S9: 1124 | T9: 1219 | U9: 6527 | V9: 4609 | W9: 4424 | X9: 2183 | Y9: 369 | Z9: 955 | AA9: 167 | AB9: 646 | AC9: 6180 | AD9: 94 | AE9: 27126 | AF9: 25648 | AG9: 195 | AH9: 1019 | AI9: 23619 | AJ9: 17982 | AK9: 56 | AL9: 13351 | AM9: 6052 | AN9: 5873 | AO9: 3827 | AP9: 3768 | AQ9: 1661 | AR9: 438 | AS9: 5083 | AT9: 1141 | AU9: 231 | AV9: 409 | AW9: 127 | AX9: 257 | AY9: 4579 | AZ9: 3318 | BA9: 7
A10: SBM1015.fcs | B10: 34385 | C10: 33666 | D10: 33296 | E10: 27707 | F10: 21 | G10: 21 | H10: 18 | I10: 18 | J10: 17 | K10: 7 | L10: 9 | M10: 0 | N10: 0 | O10: 9378 | P10: 650 | Q10: 8646 | R10: 486 | S10: 957 | T10: 1716 | U10: 4430 | V10: 2388 | W10: 2368 | X10: 585 | Y10: 193 | Z10: 357 | AA10: 160 | AB10: 166 | AC10: 3158 | AD10: 14 | AE10: 18081 | AF10: 17641 | AG10: 104 | AH10: 15 | AI10: 17232 | AJ10: 12711 | AK10: 47 | AL10: 8536 | AM10: 4280 | AN10: 3552 | AO10: 3064 | AP10: 2988 | AQ10: 669 | AR10: 502 | AS10: 4126 | AT10: 165 | AU10: 136 | AV10: 3792 | AW10: 67 | AX10: 3653 | AY10: 200 | AZ10: 146 | BA10: 2
A11: SBM1016.fcs | B11: 68990 | C11: 66382 | D11: 62287 | E11: 24096 | F11: 2069 | G11: 2063 | H11: 2052 | I11: 2051 | J11: 2051 | K11: 1541 | L11: 330 | M11: 0 | N11: 3 | O11: 9198 | P11: 1354 | Q11: 7746 | R11: 485 | S11: 230 | T11: 662 | U11: 2203 | V11: 566 | W11: 491 | X11: 1667 | Y11: 720 | Z11: 660 | AA11: 262 | AB11: 369 | AC11: 3017 | AD11: 35 | AE11: 12328 | AF11: 11598 | AG11: 134 | AH11: 524 | AI11: 10499 | AJ11: 6185 | AK11: 10 | AL11: 4949 | AM11: 711 | AN11: 3833 | AO11: 1000 | AP11: 984 | AQ11: 741 | AR11: 395 | AS11: 3931 | AT11: 1005 | AU11: 184 | AV11: 594 | AW11: 386 | AX11: 164 | AY11: 3159 | AZ11: 2169 | BA11: 14
A12: SBM1020.fcs | B12: 120938 | C12: 118043 | D12: 117453 | E12: 95879 | F12: 1432 | G12: 1414 | H12: 1371 | I12: 1362 | J12: 1361 | K12: 806 | L12: 380 | M12: 26 | N12: 6 | O12: 40720 | P12: 4743 | Q12: 34778 | R12: 1331 | S12: 1857 | T12: 4280 | U12: 16106 | V12: 7580 | W12: 7465 | X12: 3794 | Y12: 601 | Z12: 2570 | AA12: 476 | AB12: 1879 | AC12: 12354 | AD12: 58 | AE12: 52416 | AF12: 50097 | AG12: 724 | AH12: 513 | AI12: 46234 | AJ12: 25558 | AK12: 655 | AL12: 14495 | AM12: 3917 | AN12: 9535 | AO12: 9685 | AP12: 9643 | AQ12: 2797 | AR12: 720 | AS12: 18289 | AT12: 4047 | AU12: 967 | AV12: 4293 | AW12: 1267 | AX12: 2868 | AY12: 12911 | AZ12: 8578 | BA12: 73
A13: SBM1021.fcs | B13: 36221 | C13: 34723 | D13: 34052 | E13: 25348 | F13: 1 | G13: 1 | H13: 0 | I13: 0 | J13: 0 | K13: 0 | L13: 0 | M13: 0 | N13: 0 | O13: 8936 | P13: 2132 | Q13: 6627 | R13: 753 | S13: 2379 | T13: 3468 | U13: 552 | V13: 116 | W13: 85 | X13: 1790 | Y13: 25 | Z13: 263 | AA13: 83 | AB13: 154 | AC13: 3893 | AD13: 49 | AE13: 16346 | AF13: 14272 | AG13: 499 | AH13: 99 | AI13: 12810 | AJ13: 10079 | AK13: 45 | AL13: 4337 | AM13: 1711 | AN13: 2272 | AO13: 4664 | AP13: 4636 | AQ13: 835 | AR13: 582 | AS13: 2184 | AT13: 136 | AU13: 122 | AV13: 605 | AW13: 217 | AX13: 365 | AY13: 1283 | AZ13: 1030 | BA13: 15
... A76: SBM1337.fcs | B76: 50067 | C76: 47421 | D76: 43820 | E76: 22368 | F76: 361 | G76: 358 | H76: 335 | I76: 335 | J76: 332 | K76: 190 | L76: 75 | M76: 0 | N76: 2 | O76: 11444 | P76: 1689 | Q76: 9435 | R76: 314 | S76: 58 | T76: 203 | U76: 3044 | V76: 537 | W76: 424 | X76: 3699 | Y76: 365 | Z76: 2831 | AA76: 45 | AB76: 2686 | AC76: 1665 | AD76: 54 | AE76: 10116 | AF76: 9168 | AG76: 86 | AH76: 28 | AI76: 8623 | AJ76: 4259 | AK76: 11 | AL76: 1376 | AM76: 475 | AN76: 770 | AO76: 2608 | AP76: 2580 | AQ76: 261 | AR76: 107 | AS76: 3537 | AT76: 1024 | AU76: 148 | AV76: 1250 | AW76: 215 | AX76: 947 | AY76: 2143 | AZ76: 1339 | BA76: 2

Sheet Merged
A1: Record ID | B1: Procedure(s) - notes | C1: Primary pre-operative diagnosis - checkboxes (choice=Coronary artery disease) | D1: Primary pre-operative diagnosis - checkboxes (choice=Valve disease) | E1: Primary pre-operative diagnosis - checkboxes (choice=Endocarditis) | F1: Primary pre-operative diagnosis - checkboxes (choice=Heart failure) | G1: Sex assigned at birth | H1: Age at enrollment | I1: Ethnicity | J1: Race | K1: BMI | L1: Smoking | M1: Current smoker | N1: Diabetes | O1: History of cancer | P1: Cancer type, years since treatment, other | Q1: Hypertension | R1: Peripheral vascular disease | S1: Hyperlipidemia | T1: Stroke | U1: Hypothyroidism | V1: Autoimmune disease | W1: History of thrombosis/pulmonary embolism | X1: file | Y1: FlowCut-passed/Cells|count | Z1: FlowCut-passed/Cells/Single Cells|count | AA1: FlowCut-passed/Cells/Single Cells/Live Cells|count | AB1: FlowCut-passed/Cells/Single Cells/Live Cells/CD45+|count | AC1: FlowCut-passed/Cells/Single Cells/Live Cells/CD45+/CD3-/CD34+|count | AD1: FlowCut-passed/Cells/Single Cells/Live Cells/CD45+/CD3-/CD34+/CD4-CD56-|count | AE1: FlowCut-passed/Cells/Single Cells/Live Cells/CD45+/CD3-/CD34+/CD4-CD56-/CD20-CD123-|count | AF1: FlowCut-passed/Cells/Single Cells/Live Cells/CD45+/CD3-/CD34+/CD4-CD56-/CD20-CD123-/CD14-CD16-|count | AG1: FlowCut-passed/Cells/Single Cells/Live Cells/CD45+/CD3-/CD34+/CD4-CD56-/CD20-CD123-/CD14-CD16-/CD11b-CD11c-|count | AH1: FlowCut-passed/Cells/Single Cells/Live Cells/CD45+/CD3-/CD34+/CD4-CD56-/CD20-CD123-/CD14-CD16-/CD11b-CD11c-/CD34+CD38-|count | AI1: FlowCut-passed/Cells/Single Cells/Live Cells/CD45+/CD3-/CD34+/CD4-CD56-/CD20-CD123-/CD14-CD16-/CD11b-CD11c-/CD34+CD38+|count | AJ1: FlowCut-passed/Cells/Single Cells/Live Cells/CD45+/CD3-/CD34+/CD4-CD56-/CD20-CD123-/CD14-CD16-/CD11b-CD11c-/CD34+CD38+/Pro-B|count | AK1: FlowCut-passed/Cells/Single Cells/Live Cells/CD45+/CD3-/CD34+/CD4-CD56-/CD20-CD123-/CD14-CD16-/CD11b-CD11c-/CD34+CD38+/Pre-pro-B|count | AL1: FlowCut-passed/Cells/Single Cells/Live Cells/CD45+/CD3-/CD34-|count | AM1: FlowCut-passed/Cells/Single Cells/Live Cells/CD45+/CD3-/CD34-/B Cells|count | AN1: FlowCut-passed/Cells/Single Cells/Live Cells/CD45+/CD3-/CD34-/CD19-/CD20-|count | AO1: FlowCut-passed/Cells/Single Cells/Live Cells/CD45+/CD3-/CD34-/CD19-/CD20-/Early NK|count | AP1: FlowCut-passed/Cells/Single Cells/Live Cells/CD45+/CD3-/CD34-/CD19-/CD20-/Mature NK|count | AQ1: FlowCut-passed/Cells/Single Cells/Live Cells/CD45+/CD3-/CD34-/CD19-/CD20-/Non-Classical Monocyte|count | AR1: FlowCut-passed/Cells/Single Cells/Live Cells/CD45+/CD3-/CD34-/CD19-/CD20-/Classical Monocyte|count | AS1: FlowCut-passed/Cells/Single Cells/Live Cells/CD45+/CD3-/CD34-/CD19-/CD20-/CD14+/HLA-DR-|count | AT1: FlowCut-passed/Cells/Single Cells/Live Cells/CD45+/CD3-/CD34-/CD19-/CD20-/CD14+/HLA-DR-/MDSC-like|count | AU1: FlowCut-passed/Cells/Single Cells/Live Cells/CD45+/CD3-/CD34-/CD19-/CD20-/Dendritic Cells|count | AV1: FlowCut-passed/Cells/Single Cells/Live Cells/CD45+/CD3-/CD34-/CD19-/CD20-/Dendritic Cells/pDC|count | AW1: FlowCut-passed/Cells/Single Cells/Live Cells/CD45+/CD3-/CD34-/CD19-/CD20-/Dendritic Cells/cDC|count | AX1: FlowCut-passed/Cells/Single Cells/Live Cells/CD45+/CD3-/CD34-/CD19-/CD20-/Dendritic Cells/cDC/CD16+ cDC|count | AY1: FlowCut-passed/Cells/Single Cells/Live Cells/CD45+/CD3-/CD34-/CD19-/CD20-/Dendritic Cells/cDC/CD16- cDC|count | AZ1: FlowCut-passed/Cells/Single Cells/Live Cells/CD45+/CD3-/CD34-/CD19-/CD20-/CD14-/HLA-DR-|count | BA1: FlowCut-passed/Cells/Single Cells/Live Cells/CD45+/CD3-/CD34-/CD19-/CD20-/CD14-/HLA-DR-/ILC|count | BB1: FlowCut-passed/Cells/Single Cells/Live Cells/CD45+/CD3+/CD34-|count | BC1: FlowCut-passed/Cells/Single Cells/Live Cells/CD45+/CD3+/CD34-/TCRab+|count | BD1: FlowCut-passed/Cells/Single Cells/Live Cells/CD45+/CD3+/CD34-/TCRab+/NKT CD8-|count | BE1: FlowCut-passed/Cells/Single Cells/Live Cells/CD45+/CD3+/CD34-/TCRab+/NKT CD8+|count | BF1: FlowCut-passed/Cells/Single Cells/Live Cells/CD45+/CD3+/CD34-/TCRab+/T Cell|count | BG1: FlowCut-passed/Cells/Single Cells/Live Cells/CD45+/CD3+/CD34-/TCRab+/T Cell/CD4+ T cell|count | BH1: FlowCut-passed/Cells/Single Cells/Live Cells/CD45+/CD3+/CD34-/TCRab+/T Cell/CD4+ T cell/Tregs|count | BI1: FlowCut-passed/Cells/Single Cells/Live Cells/CD45+/CD3+/CD34-/TCRab+/T Cell/CD4+ T cell/CD4+/CD197+|count | BJ1: FlowCut-passed/Cells/Single Cells/Live Cells/CD45+/CD3+/CD34-/TCRab+/T Cell/CD4+ T cell/CD4+/CD197+/Naive CD4+ T Cell|count | BK1: FlowCut-passed/Cells/Single Cells/Live Cells/CD45+/CD3+/CD34-/TCRab+/T Cell/CD4+ T cell/CD4+/CD197+/Central Memory CD4+ T Cell|count | BL1: FlowCut-passed/Cells/Single Cells/Live Cells/CD45+/CD3+/CD34-/TCRab+/T Cell/CD4+ T cell/CD4+/CD197-|count | BM1: FlowCut-passed/Cells/Single Cells/Live Cells/CD45+/CD3+/CD34-/TCRab+/T Cell/CD4+ T cell/CD4+/CD197-/Effector CD4+ T Cell|count | BN1: FlowCut-passed/Cells/Single Cells/Live Cells/CD45+/CD3+/CD34-/TCRab+/T Cell/CD4+ T cell/CD279+/CD4+ T Cell|count | BO1: FlowCut-passed/Cells/Single Cells/Live Cells/CD45+/CD3+/CD34-/TCRab+/T Cell/CD4+ T cell/CD279+/CD4+ T Cell/CD4+ TPex|count | BP1: FlowCut-passed/Cells/Single Cells/Live Cells/CD45+/CD3+/CD34-/TCRab+/T Cell/CD8+ T Cell|count | BQ1: FlowCut-passed/Cells/Single Cells/Live Cells/CD45+/CD3+/CD34-/TCRab+/T Cell/CD8+ T Cell/CD279+/CD8+ T Cell|count | BR1: FlowCut-passed/Cells/Single Cells/Live Cells/CD45+/CD3+/CD34-/TCRab+/T Cell/CD8+ T Cell/CD279+/CD8+ T Cell/CD8+ TPex|count | BS1: FlowCut-passed/Cells/Single Cells/Live Cells/CD45+/CD3+/CD34-/TCRab+/T Cell/CD8+ T Cell/CD197+/CD8+ T Cell|count | BT1: FlowCut-passed/Cells/Single Cells/Live Cells/CD45+/CD3+/CD34-/TCRab+/T Cell/CD8+ T Cell/CD197+/CD8+ T Cell/Central Memory CD8+ T Cell|count | BU1: FlowCut-passed/Cells/Single Cells/Live Cells/CD45+/CD3+/CD34-/TCRab+/T Cell/CD8+ T Cell/CD197+/CD8+ T Cell/Naive CD8+ T Cell|count | BV1: FlowCut-passed/Cells/Single Cells/Live Cells/CD45+/CD3+/CD34-/TCRab+/T Cell/CD8+ T Cell/CD197-/CD8+ T Cell|count | BW1: FlowCut-passed/Cells/Single Cells/Live Cells/CD45+/CD3+/CD34-/TCRab+/T Cell/CD8+ T Cell/CD197-/CD8+ T Cell/Effector CD8+ T Cell|count | BX1: FlowCut-passed/Cells/Single Cells/Live Cells/CD45+/CD3+/CD34-/gd T cell|count
A2: 1066 | B2: CORONARY ARTERY BYPASS GRAFT x 6 with BIMA and SVG, ENDOSCOPIC SAPHENOUS VEIN HARVEST BILATERAL LEGS | C2: Checked | D2: Unchecked | E2: Unchecked | F2: Unchecked | G2: Male | H2: 55 | I2: Not Hispanic or Latino | J2: White | K2: 31.1 | L2: No | N2: No | O2: No | Q2: No | R2: No | S2: Yes | T2: No | U2: No | V2: No | W2: No | X2: SBM1066.fcs | Y2: 137438 | Z2: 134002 | AA2: 128884 | AB2: 106643 | AC2: 61 | AD2: 60 | AE2: 57 | AF2: 56 | AG2: 53 | AH2: 19 | AI2: 28 | AJ2: 0 | AK2: 1 | AL2: 45445 | AM2: 10135 | AN2: 34601 | AO2: 614 | AP2: 216 | AQ2: 2254 | AR2: 24333 | AS2: 13588 | AT2: 12140 | AU2: 2310 | AV2: 100 | AW2: 1349 | AX2: 19 | AY2: 1281 | AZ2: 5553 | BA2: 239 | BB2: 60081 | BC2: 58737 | BD2: 3124 | BE2: 425 | BF2: 47576 | BG2: 27536 | BH2: 307 | BI2: 8699 | BJ2: 219 | BK2: 8348 | BL2: 16660 | BM2: 16637 | BN2: 9363 | BO2: 6646 | BP2: 14814 | BQ2: 8343 | BR2: 5066 | BS2: 3378 | BT2: 2715 | BU2: 495 | BV2: 10383 | BW2: 10165 | BX2: 15
A3: 1069 | B3: CORONARY ARTERY BYPASS GRAFT x2, LEFT SVG | C3: Checked | D3: Unchecked | E3: Unchecked | F3: Unchecked | G3: Female | H3: 62 | I3: Unavailable | J3: Unavailable | K3: 31.6 | L3: No | N3: No | O3: No | Q3: No | R3: No | S3: Yes | T3: No | U3: No | V3: No | W3: No | X3: SBM1069.fcs | Y3: 195514 | Z3: 191326 | AA3: 189278 | AB3: 151871 | AC3: 4779 | AD3: 4746 | AE3: 4568 | AF3: 4557 | AG3: 4547 | AH3: 1025 | AI3: 3020 | AJ3: 4 | AK3: 36 | AL3: 90157 | AM3: 23770 | AN3: 63914 | AO3: 1166 | AP3: 311 | AQ3: 1218 | AR3: 31700 | AS3: 7782 | AT3: 7581 | AU3: 18229 | AV3: 3851 | AW3: 11044 | AX3: 173 | AY3: 9862 | AZ3: 7980 | BA3: 122 | BB3: 53447 | BC3: 50207 | BD3: 275 | BE3: 290 | BF3: 48822 | BG3: 32990 | BH3: 108 | BI3: 26767 | BJ3: 7187 | BK3: 16646 | BL3: 5246 | BM3: 5064 | BN3: 3693 | BO3: 2360 | BP3: 14257 | BQ3: 2877 | BR3: 733 | BS3: 8560 | BT3: 1374 | BU3: 6395 | BV3: 5420 | BW3: 4024 | BX3: 204
A4: 1309 | B4: Mitral valve replacement (a 27 mm St. Jude mechanical prosthesis) and resection of left atrial appendage | C4: Unchecked | D4: Unchecked | E4: Unchecked | F4: Unchecked | G4: Female | H4: 47 | I4: Not Hispanic or Latino | J4: Asian | K4: 26.8 | L4: No | N4: No | O4: No | Q4: No | R4: No | S4: No | T4: No | U4: No | V4: No | W4: No | X4: SBM1309.fcs | Y4: 23831 | Z4: 22120 | AA4: 20852 | AB4: 12950 | AC4: 227 | AD4: 227 | AE4: 210 | AF4: 210 | AG4: 210 | AH4: 29 | AI4: 151 | AJ4: 12 | AK4: 0 | AL4: 6366 | AM4: 777 | AN4: 5320 | AO4: 170 | AP4: 157 | AQ4: 357 | AR4: 2174 | AS4: 119 | AT4: 90 | AU4: 1120 | AV4: 146 | AW4: 864 | AX4: 18 | AY4: 805 | AZ4: 1636 | BA4: 8 | BB4: 6169 | BC4: 5589 | BD4: 40 | BE4: 53 | BF4: 5284 | BG4: 2825 | BH4: 19 | BI4: 829 | BJ4: 355 | BK4: 423 | BL4: 1907 | BM4: 1895 | BN4: 524 | BO4: 68 | BP4: 2047 | BQ4: 432 | BR4: 70 | BS4: 575 | BT4: 56 | BU4: 503 | BV4: 1411 | BW4: 886 | BX4: 23
A5: 1090 | B5: MYECTOMY SEPTAL, ERAS | C5: Unchecked | D5: Unchecked | E5: Unchecked | F5: Unchecked | G5: Male | H5: 29 | I5: Not Hispanic or Latino | J5: White | K5: 26.2 | L5: No | N5: No | O5: No | Q5: No | R5: No | S5: No | T5: No | U5: No | V5: No | W5: No | X5: SBM1090.fcs | Y5: 41092 | Z5: 39807 | AA5: 35649 | AB5: 19175 | AC5: 41 | AD5: 41 | AE5: 38 | AF5: 38 | AG5: 38 | AH5: 10 | AI5: 21 | AJ5: 0 | AK5: 0 | AL5: 7660 | AM5: 1324 | AN5: 5952 | AO5: 440 | AP5: 438 | AQ5: 1323 | AR5: 1408 | AS5: 181 | AT5: 164 | AU5: 498 | AV5: 64 | AW5: 354 | AX5: 26 | AY5: 323 | AZ5: 3864 | BA5: 61 | BB5: 11359 | BC5: 10572 | BD5: 87 | BE5: 33 | BF5: 10151 | BG5: 6357 | BH5: 11 | BI5: 3529 | BJ5: 1224 | BK5: 1968 | BL5: 2414 | BM5: 2321 | BN5: 627 | BO5: 252 | BP5: 3091 | BQ5: 438 | BR5: 110 | BS5: 1389 | BT5: 296 | BU5: 953 | BV5: 1594 | BW5: 1191 | BX5: 75
A6: 1097 | B6: MYECTOMY SEPTAL(ERAS) | C6: Unchecked | D6: Checked | E6: Unchecked | F6: Unchecked | G6: Male | H6: 68 | I6: Not Hispanic or Latino | J6: White | K6: 37.4 | L6: No | N6: No | O6: No | Q6: No | R6: No | S6: Yes | T6: No | U6: No | V6: No | W6: Yes | X6: SBM1097.fcs | Y6: 241814 | Z6: 235966 | AA6: 231326 | AB6: 203103 | AC6: 561 | AD6: 555 | AE6: 519 | AF6: 518 | AG6: 518 | AH6: 261 | AI6: 207 | AJ6: 5 | AK6: 4 | AL6: 61057 | AM6: 15743 | AN6: 43266 | AO6: 2389 | AP6: 2167 | AQ6: 8253 | AR6: 15622 | AS6: 7357 | AT6: 7000 | AU6: 4079 | AV6: 567 | AW6: 2803 | AX6: 110 | AY6: 2555 | AZ6: 21514 | BA6: 188 | BB6: 140609 | BC6: 131588 | BD6: 435 | BE6: 1690 | BF6: 125826 | BG6: 37448 | BH6: 439 | BI6: 18452 | BJ6: 4486 | BK6: 12779 | BL6: 15065 | BM6: 14964 | BN6: 5618 | BO6: 908 | BP6: 83703 | BQ6: 13383 | BR6: 1164 | BS6: 5172 | BT6: 2123 | BU6: 2777 | BV6: 76629 | BW6: 53362 | BX6: 1213
A7: 1012 | B7: Reconstruction or replacement valve sparing aortic root | C7: Unchecked | D7: Unchecked | E7: Unchecked | F7: Unchecked | G7: Female | H7: 31 | I7: Unavailable | J7: Unavailable | K7: 18.3 | L7: No | N7: No | O7: No | Q7: No | R7: No | S7: No | T7: No | U7: No | V7: No | W7: No | X7: SBM1012.fcs | Y7: 270926 | Z7: 265202 | AA7: 261135 | AB7: 167832 | AC7: 1547 | AD7: 1516 | AE7: 1454 | AF7: 1439 | AG7: 1432 | AH7: 639 | AI7: 612 | AJ7: 16 | AK7: 20 | AL7: 100530 | AM7: 24253 | AN7: 71034 | AO7: 2153 | AP7: 2647 | AQ7: 4370 | AR7: 27309 | AS7: 9535 | AT7: 9282 | AU7: 21634 | AV7: 4506 | AW7: 13647 | AX7: 155 | AY7: 12386 | AZ7: 15506 | BA7: 214 | BB7: 63098 | BC7: 60720 | BD7: 522 | BE7: 519 | BF7: 57375 | BG7: 25309 | BH7: 208 | BI7: 12451 | BJ7: 7555 | BK7: 3972 | BL7: 10943 | BM7: 10584 | BN7: 2019 | BO7: 434 | BP7: 29360 | BQ7: 5302 | BR7: 760 | BS7: 12353 | BT7: 888 | BU7: 11077 | BV7: 15587 | BW7: 10183 | BX7: 21
A8: 1048 | B8: Removal of Right atrial foreing body, PARASTERNAL BLOCK REPAIR TRICUSPID VALVE | C8: Unchecked | D8: Checked | E8: Unchecked | F8: Unchecked | G8: Female | H8: 24 | I8: Not Hispanic or Latino | J8: White | K8: 25.4 | L8: No | N8: No | O8: No | Q8: No | R8: Yes | S8: No | T8: No | U8: No | V8: No | W8: No | X8: SBM1048.fcs | Y8: 148761 | Z8: 144702 | AA8: 136700 | AB8: 94801 | AC8: 74 | AD8: 67 | AE8: 59 | AF8: 59 | AG8: 59 | AH8: 12 | AI8: 40 | AJ8: 0 | AK8: 0 | AL8: 32910 | AM8: 7765 | AN8: 24615 | AO8: 1384 | AP8: 2647 | AQ8: 4320 | AR8: 9659 | AS8: 4074 | AT8: 3993 | AU8: 1735 | AV8: 365 | AW8: 1149 | AX8: 95 | AY8: 1023 | AZ8: 12211 | BA8: 176 | BB8: 61337 | BC8: 55718 | BD8: 535 | BE8: 373 | BF8: 53500 | BG8: 30299 | BH8: 64 | BI8: 19538 | BJ8: 7660 | BK8: 10219 | BL8: 8767 | BM8: 8712 | BN8: 2332 | BO8: 695 | BP8: 20453 | BQ8: 3134 | BR8: 466 | BS8: 11251 | BT8: 1902 | BU8: 8800 | BV8: 8324 | BW8: 6821 | BX8: 163
A9: 1235 | B9: REOPERATIVE REPAIR MITRAL VALVE | C9: Unchecked | D9: Checked | E9: Unchecked | F9: Unchecked | G9: Male | H9: 25 | I9: Not Hispanic or Latino | J9: Asian | K9: 19 | L9: No | N9: No | O9: No | Q9: No | R9: No | S9: No | T9: No | U9: No | V9: No | W9: No | X9: SBM1235.fcs | Y9: 36749 | Z9: 35528 | AA9: 35018 | AB9: 30431 | AC9: 31 | AD9: 31 | AE9: 28 | AF9: 28 | AG9: 28 | AH9: 10 | AI9: 13 | AJ9: 0 | AK9: 0 | AL9: 15334 | AM9: 2031 | AN9: 13003 | AO9: 887 | AP9: 2258 | AQ9: 3213 | AR9: 1897 | AS9: 273 | AT9: 254 | AU9: 737 | AV9: 161 | AW9: 489 | AX9: 137 | AY9: 226 | AZ9: 9501 | BA9: 46 | BB9: 14869 | BC9: 12930 | BD9: 21 | BE9: 45 | BF9: 12680 | BG9: 6439 | BH9: 44 | BI9: 2208 | BJ9: 886 | BK9: 1091 | BL9: 3551 | BM9: 3323 | BN9: 391 | BO9: 83 | BP9: 5725 | BQ9: 516 | BR9: 98 | BS9: 2156 | BT9: 119 | BU9: 1962 | BV9: 2943 | BW9: 1820 | BX9: 14
A10: 1001 | B10: Repair Mitral Valve | C10: Unchecked | D10: Checked | E10: Unchecked | F10: Unchecked | G10: Female | H10: 34 | I10: Not Hispanic or Latino | J10: White | K10: 23.9 | L10: No | N10: No | O10: No | Q10: No | R10: No | S10: No | T10: No | U10: No | V10: No | W10: No | X10: SBM1001.fcs | Y10: 277764 | Z10: 265500 | AA10: 262632 | AB10: 102216 | AC10: 2698 | AD10: 2649 | AE10: 2482 | AF10: 2472 | AG10: 2463 | AH10: 547 | AI10: 1517 | AJ10: 53 | AK10: 86 | AL10: 38541 | AM10: 7265 | AN10: 29957 | AO10: 1300 | AP10: 889 | AQ10: 1026 | AR10: 13380 | AS10: 5675 | AT10: 5624 | AU10: 8258 | AV10: 2276 | AW10: 5095 | AX10: 42 | AY10: 4884 | AZ10: 5749 | BA10: 106 | BB10: 58069 | BC10: 55511 | BD10: 301 | BE10: 176 | BF10: 53861 | BG10: 32786 | BH10: 130 | BI10: 19853 | BJ10: 15656 | BK10: 3132 | BL10: 7645 | BM10: 6090 | BN10: 1144 | BO10: 201 | BP10: 19694 | BQ10: 1655 | BR10: 130 | BS10: 7234 | BT10: 298 | BU10: 6835 | BV10: 11340 | BW10: 5716 | BX10: 154
A11: 1227 | B11: REPAIR MITRAL VALVE AMPUTATION LEFT ATRIAL APPENDAGE | C11: Unchecked | D11: Checked | E11: Unchecked | F11: Unchecked | G11: Female | H11: 53 | I11: Not Hispanic or Latino | J11: White | K11: 40.3 | L11: No | N11: No | O11: No | Q11: No | R11: No | S11: No | T11: No | U11: No | V11: No | W11: No | X11: SBM1227.fcs | Y11: 149245 | Z11: 146074 | AA11: 145481 | AB11: 135150 | AC11: 37 | AD11: 36 | AE11: 33 | AF11: 31 | AG11: 30 | AH11: 6 | AI11: 18 | AJ11: 0 | AK11: 0 | AL11: 49041 | AM11: 6193 | AN11: 41403 | AO11: 4477 | AP11: 5787 | AQ11: 7834 | AR11: 8778 | AS11: 2067 | AT11: 1389 | AU11: 2499 | AV11: 299 | AW11: 1924 | AX11: 440 | AY11: 1345 | AZ11: 28939 | BA11: 285 | BB11: 85539 | BC11: 77590 | BD11: 344 | BE11: 132 | BF11: 74877 | BG11: 57384 | BH11: 254 | BI11: 16496 | BJ11: 5208 | BK11: 9764 | BL11: 35449 | BM11: 34754 | BN11: 1904 | BO11: 581 | BP11: 14873 | BQ11: 1406 | BR11: 341 | BS11: 3286 | BT11: 495 | BU11: 2532 | BV11: 10397 | BW11: 5415 | BX11: 22
A12: 1154 | B12: Repair Mitral Valve (ERAS) Repair Tricuspid Valve Coronary Artery Bypass Graft | C12: Checked | D12: Unchecked | E12: Unchecked | F12: Checked | G12: Male | H12: 61 | I12: Not Hispanic or Latino | J12: Black or African American | K12: 24.5 | L12: No | N12: No | O12: No | Q12: No | R12: No | S12: No | T12: No | U12: No | V12: No | W12: No | X12: SBM1154.fcs | Y12: 105939 | Z12: 97892 | AA12: 91684 | AB12: 60528 | AC12: 335 | AD12: 321 | AE12: 308 | AF12: 303 | AG12: 302 | AH12: 106 | AI12: 134 | AJ12: 2 | AK12: 3 | AL12: 32196 | AM12: 7484 | AN12: 23914 | AO12: 1421 | AP12: 1744 | AQ12: 3775 | AR12: 8938 | AS12: 1834 | AT12: 1801 | AU12: 4384 | AV12: 399 | AW12: 2854 | AX12: 568 | AY12: 1902 | AZ12: 8792 | BA12: 45 | BB12: 27484 | BC12: 25403 | BD12: 396 | BE12: 217 | BF12: 23782 | BG12: 16705 | BH12: 228 | BI12: 6381 | BJ12: 1479 | BK12: 4704 | BL12: 9085 | BM12: 8302 | BN12: 3522 | BO12: 1031 | BP12: 6384 | BQ12: 1591 | BR12: 223 | BS12: 1200 | BT12: 419 | BU12: 718 | BV12: 4897 | BW12: 2190 | BX12: 87
A13: 1003 | B13: REPLACE SYSTEMIC TRICUSPID VALVE IN CCTGA CLOSURE PATENT FORAMEN OVALE PLACEMENT VENTRICUALR EPICARDIAL LEADS | C13: Unchecked | D13: Checked | E13: Unchecked | F13: Unchecked | G13: Female | H13: 35 | I13: Not Hispanic or Latino | J13: White | K13: 26.5 | L13: No | N13: No | O13: No | Q13: No | R13: No | S13: No | T13: No | U13: No | V13: No | W13: No | X13: SBM1003.fcs | Y13: 321845 | Z13: 314310 | AA13: 309191 | AB13: 181785 | AC13: 3329 | AD13: 3197 | AE13: 2976 | AF13: 2935 | AG13: 2904 | AH13: 1162 | AI13: 407 | AJ13: 9 | AK13: 20 | AL13: 90578 | AM13: 35124 | AN13: 51872 | AO13: 1659 | AP13: 927 | AQ13: 2509 | AR13: 21579 | AS13: 11303 | AT13: 10861 | AU13: 13356 | AV13: 2863 | AW13: 8637 | AX13: 317 | AY13: 6310 | AZ13: 9556 | BA13: 122 | BB13: 82123 | BC13: 75753 | BD13: 618 | BE13: 651 | BF13: 72429 | BG13: 46060 | BH13: 125 | BI13: 38228 | BJ13: 36081 | BK13: 1486 | BL13: 5701 | BM13: 2403 | BN13: 5549 | BO13: 3054 | BP13: 24060 | BQ13: 3824 | BR13: 736 | BS13: 8187 | BT13: 89 | BU13: 7976 | BV13: 15216 | BW13: 788 | BX13: 165
... A16: 1146 | B16: Replacement Aortic Valve, ERAS (Mechanical) | C16: Unchecked | D16: Checked | E16: Unchecked | F16: Unchecked | G16: Male | H16: 47 | I16: Not Hispanic or Latino | J16: White | K16: 22.8 | L16: No | N16: No | O16: No | Q16: No | R16: No | S16: No | T16: No | U16: No | V16: No | W16: No | X16: SBM1146.fcs | Y16: 120485 | Z16: 116000 | AA16: 110462 | AB16: 69007 | AC16: 161 | AD16: 157 | AE16: 153 | AF16: 153 | AG16: 153 | AH16: 100 | AI16: 31 | AJ16: 1 | AK16: 0 | AL16: 46114 | AM16: 2769 | AN16: 42546 | AO16: 1737 | AP16: 1542 | AQ16: 1563 | AR16: 24230 | AS16: 10455 | AT16: 10315 | AU16: 6220 | AV16: 624 | AW16: 4547 | AX16: 149 | AY16: 3881 | AZ16: 7841 | BA16: 82 | BB16: 21952 | BC16: 20127 | BD16: 261 | BE16: 212 | BF16: 18773 | BG16: 6943 | BH16: 38 | BI16: 3631 | BJ16: 1288 | BK16: 2093 | BL16: 2953 | BM16: 2895 | BN16: 1085 | BO16: 517 | BP16: 10899 | BQ16: 2622 | BR16: 550 | BS16: 3334 | BT16: 1048 | BU16: 2115 | BV16: 7092 | BW16: 3758 | BX16: 29
A17: 1160 | B17: Minimally Invasive Replacement Aortic Valve, ERAS | C17: Unchecked | D17: Unchecked | E17: Unchecked | F17: Unchecked | G17: Male | H17: 65 | I17: Not Hispanic or Latino | J17: White | K17: 24.5 | L17: No | N17: No | O17: Yes | P17: basal cell carcinoma of the skin right abdomen | Q17: No | R17: No | S17: Yes | T17: No | U17: No | V17: No | W17: No | X17: SBM1160.fcs | Y17: 99510 | Z17: 93685 | AA17: 90392 | AB17: 55396 | AC17: 282 | AD17: 277 | AE17: 271 | AF17: 271 | AG17: 271 | AH17: 142 | AI17: 109 | AJ17: 0 | AK17: 2 | AL17: 32289 | AM17: 3261 | AN17: 28515 | AO17: 2174 | AP17: 6082 | AQ17: 5683 | AR17: 8971 | AS17: 2751 | AT17: 2632 | AU17: 3263 | AV17: 275 | AW17: 2653 | AX17: 422 | AY17: 2028 | AZ17: 14793 | BA17: 69 | BB17: 22349 | BC17: 20906 | BD17: 259 | BE17: 255 | BF17: 19213 | BG17: 11320 | BH17: 131 | BI17: 5266 | BJ17: 2098 | BK17: 2784 | BL17: 5161 | BM17: 5052 | BN17: 1286 | BO17: 290 | BP17: 6666 | BQ17: 1860 | BR17: 163 | BS17: 1839 | BT17: 332 | BU17: 1471 | BV17: 4636 | BW17: 3976 | BX17: 8
A18: 1165 | B18: Repair/Replacement Mitral Valve | C18: Unchecked | D18: Unchecked | E18: Unchecked | F18: Unchecked | G18: Male | H18: 66 | I18: Not Hispanic or Latino | J18: White | K18: 28.9 | L18: No | N18: No | O18: No | Q18: Yes | R18: No | S18: No | T18: No | U18: No | V18: No | W18: No | X18: SBM1165.fcs | Y18: 232949 | Z18: 206715 | AA18: 194926 | AB18: 110284 | AC18: 166 | AD18: 160 | AE18: 142 | AF18: 142 | AG18: 141 | AH18: 48 | AI18: 79 | AJ18: 0 | AK18: 3 | AL18: 53013 | AM18: 5540 | AN18: 47119 | AO18: 1474 | AP18: 2304 | AQ18: 7043 | AR18: 28715 | AS18: 3147 | AT18: 3091 | AU18: 3650 | AV18: 506 | AW18: 2323 | AX18: 405 | AY18: 1640 | AZ18: 13226 | BA18: 157 | BB18: 56573 | BC18: 54079 | BD18: 111 | BE18: 237 | BF18: 52511 | BG18: 26321 | BH18: 158 | BI18: 10207 | BJ18: 2443 | BK18: 7267 | BL18: 13234 | BM18: 13181 | BN18: 1739 | BO18: 374 | BP18: 22946 | BQ18: 2649 | BR18: 288 | BS18: 4297 | BT18: 2348 | BU18: 1810 | BV18: 16832 | BW18: 6730 | BX18: 49
A19: 1158 | B19: REPLACEMENT AORTIC ROOT REPAIR OR REPLACEMENT HEMI ARCH ASCENDING AORTA CORONARY ARTERY BYPASS GRAFT x1, COMPOSITE AORTIC ROOT | C19: Checked | D19: Unchecked | E19: Unchecked | F19: Unchecked | G19: Male | H19: 58 | I19: Not Hispanic or Latino | J19: White | K19: 32.6 | L19: No | N19: No | O19: No | Q19: Yes | R19: No | S19: Yes | T19: No | U19: No | V19: Yes | W19: No | X19: SBM1158.fcs | Y19: 214097 | Z19: 190556 | AA19: 189560 | AB19: 124663 | AC19: 241 | AD19: 235 | AE19: 222 | AF19: 217 | AG19: 208 | AH19: 56 | AI19: 76 | AJ19: 1 | AK19: 1 | AL19: 48445 | AM19: 6964 | AN19: 40514 | AO19: 2326 | AP19: 2358 | AQ19: 3722 | AR19: 15650 | AS19: 4558 | AT19: 4266 | AU19: 4097 | AV19: 609 | AW19: 3187 | AX19: 236 | AY19: 2702 | AZ19: 17033 | BA19: 175 | BB19: 72912 | BC19: 66004 | BD19: 1116 | BE19: 2749 | BF19: 57409 | BG19: 36438 | BH19: 283 | BI19: 24524 | BJ19: 11148 | BK19: 12017 | BL19: 8734 | BM19: 8574 | BN19: 8198 | BO19: 5403 | BP19: 17653 | BQ19: 5720 | BR19: 3767 | BS19: 12292 | BT19: 1419 | BU19: 10653 | BV19: 4037 | BW19: 3143 | BX19: 48
A20: 1091 | B20: BENTALL WITH ASCENDING HEMIARCH, LEFT LEG ENDOSCOPIC SAPHENOUS VEIN HARVEST | C20: Unchecked | D20: Checked | E20: Unchecked | F20: Checked | G20: Female | H20: 61 | I20: Not Hispanic or Latino | J20: White | K20: 33.8 | L20: No | N20: No | O20: No | Q20: Yes | R20: No | S20: Yes | T20: No | U20: No | V20: No | W20: No | X20: SBM1091.fcs | Y20: 219518 | Z20: 216315 | AA20: 196851 | AB20: 93614 | AC20: 353 | AD20: 353 | AE20: 336 | AF20: 330 | AG20: 328 | AH20: 185 | AI20: 19 | AJ20: 0 | AK20: 0 | AL20: 34564 | AM20: 4324 | AN20: 29353 | AO20: 683 | AP20: 2649 | AQ20: 6757 | AR20: 11811 | AS20: 10308 | AT20: 10065 | AU20: 1695 | AV20: 250 | AW20: 1293 | AX20: 116 | AY20: 901 | AZ20: 13136 | BA20: 123 | BB20: 57919 | BC20: 55364 | BD20: 253 | BE20: 356 | BF20: 53436 | BG20: 38925 | BH20: 91 | BI20: 26088 | BJ20: 5447 | BK20: 18128 | BL20: 9765 | BM20: 9624 | BN20: 2212 | BO20: 829 | BP20: 12392 | BQ20: 1112 | BR20: 170 | BS20: 3140 | BT20: 1220 | BU20: 1625 | BV20: 8487 | BW20: 5886 | BX20: 123
A21: 1047 | B21: COMPOSITE AORTIC ROOT, RECONSTRUCTION HEMIARCH REPLACEMENT VALVE SPARING AORTIC ROOT MAZE PROCEDURE/ Left atrial appendage ligation | C21: Unchecked | D21: Checked | E21: Unchecked | F21: Unchecked | G21: Male | H21: 69 | I21: Not Hispanic or Latino | J21: White | K21: 23.5 | L21: No | N21: No | O21: No | Q21: Yes | R21: No | S21: Yes | T21: No | U21: No | V21: No | W21: No | X21: SBM1047.fcs | Y21: 78807 | Z21: 74432 | AA21: 72740 | AB21: 51195 | AC21: 531 | AD21: 515 | AE21: 491 | AF21: 488 | AG21: 487 | AH21: 167 | AI21: 256 | AJ21: 11 | AK21: 6 | AL21: 33201 | AM21: 2892 | AN21: 28840 | AO21: 1075 | AP21: 491 | AQ21: 4550 | AR21: 13389 | AS21: 4064 | AT21: 3859 | AU21: 5159 | AV21: 485 | AW21: 3925 | AX21: 111 | AY21: 3465 | AZ21: 8058 | BA21: 81 | BB21: 16336 | BC21: 15513 | BD21: 199 | BE21: 133 | BF21: 14466 | BG21: 7424 | BH21: 187 | BI21: 3483 | BJ21: 714 | BK21: 2585 | BL21: 3166 | BM21: 3130 | BN21: 690 | BO21: 136 | BP21: 5861 | BQ21: 1647 | BR21: 146 | BS21: 1485 | BT21: 621 | BU21: 786 | BV21: 3817 | BW21: 3168 | BX21: 16
A22: 1210 | B22: Coronary Artery Bypass Graft | C22: Checked | D22: Unchecked | E22: Unchecked | F22: Unchecked | G22: Male | H22: 59 | I22: Not Hispanic or Latino | J22: White | K22: 27.5 | L22: No | N22: No | O22: No | Q22: Yes | R22: No | S22: Yes | T22: No | U22: No | V22: No | W22: No | X22: SBM1210.fcs | Y22: 66184 | Z22: 59940 | AA22: 58794 | AB22: 20753 | AC22: 432 | AD22: 422 | AE22: 396 | AF22: 395 | AG22: 393 | AH22: 147 | AI22: 186 | AJ22: 2 | AK22: 4 | AL22: 10268 | AM22: 4359 | AN22: 5368 | AO22: 203 | AP22: 30 | AQ22: 123 | AR22: 1915 | AS22: 605 | AT22: 560 | AU22: 1231 | AV22: 279 | AW22: 661 | AX22: 40 | AY22: 594 | AZ22: 1435 | BA22: 20 | BB22: 9664 | BC22: 9186 | BD22: 30 | BE22: 45 | BF22: 8927 | BG22: 5747 | BH22: 30 | BI22: 3604 | BJ22: 701 | BK22: 2546 | BL22: 1653 | BM22: 1594 | BN22: 416 | BO22: 103 | BP22: 2729 | BQ22: 1005 | BR22: 79 | BS22: 765 | BT22: 259 | BU22: 427 | BV22: 1883 | BW22: 1577 | BX22: 5
A23: 1155 | B23: Coronary Artery Bypass Graft | C23: Checked | D23: Unchecked | E23: Unchecked | F23: Unchecked | G23: Male | H23: 89 | I23: Not Hispanic or Latino | J23: White | K23: 22.8 | L23: No | N23: Yes | O23: No | Q23: Yes | R23: No | S23: Yes | T23: Yes | U23: No | V23: No | W23: No | X23: SBM1155.fcs | Y23: 348111 | Z23: 320999 | AA23: 317961 | AB23: 189871 | AC23: 681 | AD23: 661 | AE23: 641 | AF23: 635 | AG23: 632 | AH23: 223 | AI23: 292 | AJ23: 1 | AK23: 2 | AL23: 74044 | AM23: 13874 | AN23: 59298 | AO23: 2902 | AP23: 3767 | AQ23: 4702 | AR23: 34939 | AS23: 4768 | AT23: 686 | AU23: 6655 | AV23: 2254 | AW23: 3526 | AX23: 361 | AY23: 2871 | AZ23: 15353 | BA23: 125 | BB23: 113906 | BC23: 104450 | BD23: 943 | BE23: 1434 | BF23: 98560 | BG23: 71002 | BH23: 163 | BI23: 41835 | BJ23: 10625 | BK23: 27403 | BL23: 22552 | BM23: 21350 | BN23: 3133 | BO23: 453 | BP23: 24339 | BQ23: 2576 | BR23: 143 | BS23: 2919 | BT23: 874 | BU23: 1808 | BV23: 20550 | BW23: 9545 | BX23: 535
A24: 1169 | B24: Coronary Artery Bypass Graft | C24: Checked | D24: Unchecked | E24: Unchecked | F24: Unchecked | G24: Female | H24: 58 | I24: Not Hispanic or Latino | J24: Black or African American | K24: 47 | L24: No | N24: Yes | O24: No | Q24: Yes | R24: No | S24: Yes | T24: No | U24: No | V24: No | W24: No | X24: SBM1169.fcs | Y24: 123596 | Z24: 120354 | AA24: 110696 | AB24: 48343 | AC24: 310 | AD24: 246 | AE24: 238 | AF24: 238 | AG24: 238 | AH24: 50 | AI24: 152 | AJ24: 5 | AK24: 1 | AL24: 23706 | AM24: 6770 | AN24: 16594 | AO24: 673 | AP24: 994 | AQ24: 4092 | AR24: 1450 | AS24: 885 | AT24: 857 | AU24: 2518 | AV24: 321 | AW24: 1404 | AX24: 513 | AY24: 376 | AZ24: 9823 | BA24: 72 | BB24: 23327 | BC24: 13636 | BD24: 86 | BE24: 40 | BF24: 13287 | BG24: 8815 | BH24: 24 | BI24: 2173 | BJ24: 593 | BK24: 1431 | BL24: 6023 | BM24: 5504 | BN24: 291 | BO24: 70 | BP24: 3987 | BQ24: 335 | BR24: 43 | BS24: 1291 | BT24: 211 | BU24: 1000 | BV24: 2493 | BW24: 1487 | BX24: 11
A25: 1156 | B25: Coronary Artery Bypass Graft Repair Mitral Valve | C25: Checked | D25: Checked | E25: Unchecked | F25: Unchecked | G25: Female | H25: 78 | I25: Not Hispanic or Latino | J25: White | K25: 26.9 | L25: No | N25: No | O25: No | Q25: Yes | R25: No | S25: Yes | T25: No | U25: No | V25: No | W25: No | X25: SBM1156.fcs | Y25: 94953 | Z25: 87185 | AA25: 85970 | AB25: 55444 | AC25: 641 | AD25: 615 | AE25: 564 | AF25: 557 | AG25: 549 | AH25: 152 | AI25: 334 | AJ25: 64 | AK25: 12 | AL25: 26662 | AM25: 6097 | AN25: 19150 | AO25: 1374 | AP25: 2846 | AQ25: 2831 | AR25: 9192 | AS25: 4548 | AT25: 4358 | AU25: 2090 | AV25: 269 | AW25: 1412 | AX25: 172 | AY25: 1162 | AZ25: 6759 | BA25: 72 | BB25: 26319 | BC25: 24480 | BD25: 319 | BE25: 271 | BF25: 22811 | BG25: 18172 | BH25: 338 | BI25: 8746 | BJ25: 4190 | BK25: 3967 | BL25: 7403 | BM25: 7256 | BN25: 4061 | BO25: 2269 | BP25: 3721 | BQ25: 2150 | BR25: 963 | BS25: 766 | BT25: 226 | BU25: 519 | BV25: 2396 | BW25: 1824 | BX25: 15
A26: 1162 | B26: Coronary Artery Bypass Graft (BIMA) | C26: Checked | D26: Unchecked | E26: Unchecked | F26: Unchecked | G26: Male | H26: 53 | I26: Not Hispanic or Latino | J26: White | K26: 30.1 | L26: No | N26: No | O26: No | Q26: Yes | R26: No | S26: Yes | T26: No | U26: No | V26: No | W26: No | X26: SBM1162.fcs | Y26: 135286 | Z26: 129503 | AA26: 117499 | AB26: 71413 | AC26: 640 | AD26: 632 | AE26: 601 | AF26: 600 | AG26: 599 | AH26: 260 | AI26: 255 | AJ26: 5 | AK26: 2 | AL26: 42949 | AM26: 5080 | AN26: 36468 | AO26: 982 | AP26: 871 | AQ26: 2221 | AR26: 16155 | AS26: 6379 | AT26: 6188 | AU26: 6344 | AV26: 829 | AW26: 4552 | AX26: 20 | AY26: 4315 | AZ26: 11021 | BA26: 148 | BB26: 26899 | BC26: 24696 | BD26: 424 | BE26: 141 | BF26: 22934 | BG26: 11778 | BH26: 115 | BI26: 5611 | BJ26: 1616 | BK26: 3757 | BL26: 5308 | BM26: 5280 | BN26: 1356 | BO26: 692 | BP26: 9307 | BQ26: 3025 | BR26: 406 | BS26: 2138 | BT26: 799 | BU26: 1300 | BV26: 6817 | BW26: 5862 | BX26: 20
A27: 1121 | B27: CORONARY ARTERY BYPASS GRAFT X 3 with LIMA and SVG , ENDARTERECTOMY, ENDOSCOPIC SAPHENOUS VEIN HARVEST LEFT LEG , ERAS INSERTION OF CENTRIMAG RIGHT VENTRICULAR ASSIST DEVICE | C27: Checked | D27: Unchecked | E27: Unchecked | F27: Unchecked | G27: Male | H27: 69 | I27: Not Hispanic or Latino | J27: Asian | K27: 22 | L27: No | N27: Yes | O27: No | Q27: Yes | R27: No | S27: Yes | T27: No | U27: No | V27: No | W27: No | X27: SBM1121.fcs | Y27: 205943 | Z27: 200135 | AA27: 194780 | AB27: 141444 | AC27: 200 | AD27: 200 | AE27: 182 | AF27: 181 | AG27: 179 | AH27: 74 | AI27: 68 | AJ27: 0 | AK27: 6 | AL27: 73229 | AM27: 14299 | AN27: 57956 | AO27: 2701 | AP27: 1530 | AQ27: 5493 | AR27: 27346 | AS27: 8684 | AT27: 8235 | AU27: 5591 | AV27: 631 | AW27: 4571 | AX27: 1610 | AY27: 2299 | AZ27: 22117 | BA27: 169 | BB27: 66838 | BC27: 63745 | BD27: 75 | BE27: 135 | BF27: 63066 | BG27: 29342 | BH27: 372 | BI27: 10885 | BJ27: 2168 | BK27: 8169 | BL27: 15483 | BM27: 14999 | BN27: 5073 | BO27: 703 | BP27: 30667 | BQ27: 6092 | BR27: 646 | BS27: 1683 | BT27: 1236 | BU27: 402 | BV27: 27892 | BW27: 15173 | BX27: 32
A28: 1026 | B28: CORONARY ARTERY BYPASS GRAFT x1, LEFT SAPHENOUS EVH | C28: Checked | D28: Unchecked | E28: Unchecked | F28: Unchecked | G28: Female | H28: 58 | I28: Hispanic or Latino | J28: Unavailable | K28: 30.7 | L28: No | N28: No | O28: No | Q28: Yes | R28: No | S28: Yes | T28: No | U28: No | V28: No | W28: No | X28: SBM1026.fcs | Y28: 259455 | Z28: 252631 | AA28: 242041 | AB28: 173053 | AC28: 348 | AD28: 337 | AE28: 316 | AF28: 313 | AG28: 311 | AH28: 145 | AI28: 142 | AJ28: 16 | AK28: 1 | AL28: 91092 | AM28: 35108 | AN28: 53897 | AO28: 4116 | AP28: 2535 | AQ28: 3082 | AR28: 18819 | AS28: 2263 | AT28: 2165 | AU28: 14814 | AV28: 2109 | AW28: 11865 | AX28: 800 | AY28: 10253 | AZ28: 16059 | BA28: 180 | BB28: 80290 | BC28: 72422 | BD28: 658 | BE28: 475 | BF28: 69674 | BG28: 47233 | BH28: 60 | BI28: 12537 | BJ28: 1468 | BK28: 10548 | BL28: 29598 | BM28: 29371 | BN28: 4043 | BO28: 788 | BP28: 19847 | BQ28: 3939 | BR28: 434 | BS28: 2247 | BT28: 1386 | BU28: 708 | BV28: 16317 | BW28: 12098 | BX28: 257
